Workbook
Name Blankettinfo: översikt!$A$32
Name Dagen: översikt!$A$33
Name Namn: översikt!$B$3
Name Pnr: översikt!$B$4
Name Rubrik: översikt!$G$1
Name Saldo_apr: april!$I$2
Name Saldo_aug: augusti!$I$2
Name Saldo_dec: december!$I$2
Name Saldo_feb: februari!$I$2
Name Saldo_jan: januari!$I$2
Name Saldo_jul: juli!$I$2
Name Saldo_jun: juni!$I$2
Name Saldo_maj: maj!$I$2
Name Saldo_mar: mars!$I$2
Name Saldo_nov: november!$I$2
Name Saldo_okt: oktober!$I$2
Name Saldo_sep: september!$I$2
Name Tjgrad: översikt!$B$6
Name UB_apr: april!$I$4
Name UB_aug: augusti!$I$4
Name UB_dec: december!$I$4
Name UB_feb: februari!$I$4
Name UB_jan: januari!$I$4
Name UB_jul: juli!$I$4
Name UB_jun: juni!$I$4
Name UB_maj: maj!$I$4
Name UB_mar: mars!$I$4
Name UB_nov: november!$I$4
Name UB_okt: oktober!$I$4
Name UB_sep: september!$I$4

Sheet hjälp
A1: Om blanketten
A2: Flexblanketten innehåller ett antal funktioner för automatisk summering. För att detta ska fungera får inga rader, kolumner eller celler infogas eller tas bort – det kan innebära att beräkningarna inte blir korrekta. Eventuella frågor om blanketten skickas till lon@liu.se Dokumentet innehåller en flik för varje månad plus en översiktsflik.
A4: Fliken "Översikt"
A5: På översiktsfliken anges följande: • namn • personnummer • ingående flexsaldo (anges i decimal form med komma som decimalseparator) • tjänstgöringsgrad i procent Därefter behöver inga uppgifter på fliken ändras. På översiktsfliken syns också en sammanställning över saldo per månad, ackumulerat saldo samt eventuella justeringar av saldot. Detta beräknas automatiskt utifrån de uppgifter som skrivs in på månadsflikarna. Här framgår också referenstid per månad, dagar med arbetstidsförkortning och klämdagar. Den angivna referenstiden här är beräknad utifrån den tjänstgöringsgrad som angetts enligt ovan. Som standard kopieras den tjänstgöringsgrad som anges på fliken ”Översikt” till respektive månadsflik. Om du har olika tjänstgöringsgrad under året justeras procentsatsen direkt på respektive månadsflik. Du kan kontrollera så att rätt procentsats har angetts genom att titta i kolumnen ”Tj-grad” på översiktsfliken.
C6: Skrolla nedåt för mera text
A7: Månadsflikarna
A8: Alla klockslag och tider anges med timmar och minuter separerade av kolon (om inte annat anges). All sammanräkning sker automatiskt och utgående saldo för en månad förs över som ingående saldo följande månad. Exempel på hur tidsangivelser skrivs in: • klockan åtta på förmiddagen anges som 8:00 • klockan halv fem på eftermiddagen anges som 16:30 • trekvarts timme (45 minuter) anges som 0:45 Omräkning till tid i decimalform sker automatiskt. Sammanräkningen beaktar också klämdagar och dagar med arbetstidsförkortning – ingen korrigering för detta behöver skrivas in. Klämdagar är gråmarkerade (arbetsfria dagar) och dagar med arbetstidsförkortning är gulmarkerade. (Om du arbetar koncentrerad deltid och/eller har semester en dag med arbetstidsförkortning kan antalet timmar behöva justeras manuellt.) Om flexsaldot behöver korrigeras, till exempel om kompensation för arbetad tid betalats ut i form av övertids- eller mertidsersättning, skrivs detta in i den ljusgrå rutan ”Ev korrigering”. Antalet timmar skrivs här i decimal form – med minustecken om flexsaldot ska minskas.
A10: Närvarotid
A11: För varje dag anges klockslag då arbetsdagen börjar respektive slutar. När ”Slutar”-tiden för respektive dag skrivs in räknas närvarotiden ut. Lunchen anges med automatik till 30 minuter – om lunchen varat längre fylls detta i manuellt genom att skriva över uppgiften 00:30 (start- och sluttid för lunchen behöver inte anges utan bara längden). Om du inte haft någon lunch (till exempel om du arbetar deltid) raderas uppgiften för lunch (det går inte att skriva noll i denna ruta).
A13: Ledigheter och avvikelser från dagregistreringen
A14: Vid ledighet fylls i vissa fall antalet timmar i med automatik. Om du skriver något av följande i kolumnen "Kommentar" fylls frånvaro för hel dag i: • Semester • Sjuk • Vård av barn De dagar du har sådan ledighet ska således inget skrivas i kolumnerna för närvarotid! Om du har annan frånvaro under dagen (eller del av denna) skrivs anledningen in i kolumnen "Kommentar". Frånvaro under del av dagen för t.ex. sjukdom anges då som "Sjuk del av dagen", "Vård av barn 4 tim" eller liknande. I dessa fall anges klockslag samt om det är plus- eller minustid så att antal timmar i kolumnen "Avvik tim" blir korrekt. (Den automatiska beräkningen av timmar görs som om du varit frånvarande hela dagen. För dig som arbetar koncentrerad deltid är denna beräkning inte alltid korrekt utan behöver korrigeras. Skriv då något annat än exakt det som anges i punktlistan ovan så kan antalet timmar fyllas i manuellt (exempelvis "semesterdag", "sjukdom" eller "vård av sjukt barn".)
A16: Informationsrutor på månadsflikarna
A17: Högst upp på månadsflikarna finns ett antal rutor: • Tj-grad: Den tjänstgöringsgrad som angetts på fliken Översikt. Om den behöver justeras en viss månad anges den nya omfattningen i denna ruta. • Närvaro: Summa närvarotid (med lunch frånräknad) i decimal form för aktuell månad. • Avvikelse: Summa avvikelsetid (i förekommande fall) i decimal form för aktuell månad. • Totalt: Närvarotid plus avvikelsetid för aktuell månad. • Ev korrigering: Eventuell korrigering av flexsaldot som gjorts denna månad (anges ’decimalt’ med kommatecken; om två och en halv timme utbetalats som lön anges det som -2,5). • Referenstid: Antal arbetstimmar för månaden. • Månadens saldo: Antal timmar totalt minus referenstiden för aktuell månad. Denna siffra visas också på fliken Översikt. • Ing flex: Ingående flexsaldo för månaden. • Utg flex: Utgående flexsaldo för månaden (beräknat som ingående flexsaldoplus saldo plus ev korrigering). I kolumnen ”Saldo hittills” beräknas den aktuella månadens saldo dag för dag. Här kan du alltså se hur du ligger till under innevarande månad jämfört med normtiden.
A19: För dig som arbetar koncentrerad deltid
A20: Kolumnen "Saldo hittills" jämför närvarotid och avvikelsetid hittills under månaden med den normaltid som gäller. Beräkningen beaktar dock inte schema för koncentrerad deltid utan baseras på att antalet timmar per dag är jämnt fördelat under arbetsveckan. Det innebär att kolumnen inte ger en rättvisande bild av hur du ligger till jämfört med normalarbetstiden. Beroende på hur arbetsdagarna faller ut under månaden kan det också uppstå plus- eller minussaldo i slutet av månaden trots att du arbetat enligt ditt schema för koncentrerad deltid. Det beror på att normalarbetstiden beräknas som aktuell procentandel av tiden för heltid varje månad. En sådan differens vid månadsskiftet jämnas ut under efterföljande månad(er) beroende på hur många vardagar det är i respektive månad och vilka vardagar du har som arbetsdagar.
A22: Kolumner för egen tidsregistrering
A23: I kolumnerna P-T kan du notera timmar med egen indelning. Respektive kolumn summeras per månad och på rad 6 kan du ange en rubrik. Noteringarna i dessa kolumner påverkar inte flexsaldot men kan användas för t.ex. en enklare form av tidredovisning.

Sheet exempel
A1: Exempel på hur du fyller i blanketten
A3: Lunch
A4: Om inget annat anges sätts lunchen till 30 minuter. Om någon annan tid ska anges skriver du in den manuellt. Har du inte haft någon lunch alls raderar du innehållet helt - det går inte att skriva värdet noll (0).
A6: Kommer och går under dagen
A7: Om du har ett uppehåll utöver lunchen anger du detta som "Avvikelse från dagregistreringen". Exempel: du börjar kl 8, har 30 minuter lunch och sedan ytterligare en timmes uppehåll mellan 15 och 16 innan du går hem kl 17:30. Skriv då 8:00 som "Börjar" och 17:30 som "Slutar". Lunchen anges som 30 minuter och sedan skriver du som "Avvikelse från dagregistreringen" fr.o.m 15:00 t.o.m. 16:00 samt ett minus i kolumn L. Som "Avvik tim" noteras då -1:00 timme och totalt för dagen räknas 8 timmar (9 tim i kolumn D och -1 tim i kolumn M).
A9: Jobbar ytterligare en stund utanför vanlig arbetstid
A10: Om du till exempel jobbar en stund hemma på kvällen anges det som "Avvikelse från dagregistreringen". Skriv först tiderna för det vanliga arbetspasset under "Närvarotid". Den extra tiden på kvällen anges som avvikelse (fr.o.m - t.o.m.) samt ett plustecken i kolumn L. Tiden läggs då till ditt saldo för dagen.
A12: Hur gör jag med kompledighet?
A13: Om du är kompledig (alltså tar ut över- eller mertid i ledighet) en dag eller del av dag anges detta om 'plustid' under "Avvikelse från dagregistreringen". Skriv klockslag så det motsvarar det antal timmar som du tar ut.
A15: Hur gör jag med flexledighet?
A16: Om du tar ut ledighet som ska räknas av från ditt flexsaldo behöver du inte ange några tider för detta. Däremot kan det vara lämpligt att skriva exempelvis "Flexledig" i kommentarkolumnen.
A18: Hur gör jag om tjänstgöringsgraden förändras?
A19: På fliken Översikt anges en tjänstgöringsgrad som normalt används för hela året. Om din tjänstgöringsgrad förändras under året skriver du på respektive månadsflik in aktuell tjänstgöringsgrad (ruta B4). Referenstid och övriga beräkningar sker då utifrån denna procentsats. Blanketten räknar med samma procentsats för hela månaden. Om du byter tjänstgöringsgrad någon gång under en månad måste därför korrigering ske manuellt. Antingen registrerar du plus- eller minusavvikelse dag för dag eller också kan du i rutan "Ev korrigering" ange det antal timmar som den beräknade referenstiden ska korrigeras med.

Sheet översikt
G1: Flex 2026
A3: Namn | B3: Håkan Stensby
A4: Personnummer | B4: 19770217-6418
A5: Ingående flex för året | B5: 6 | C5: (Anges i decimaler med kommatecken!)
A6: Tjänstgöringsgrad | B6: 1
A8: Månad | B8: Ref tid | C8: Tj-grad | D8: Saldo | E8: Ack saldo | F8: Just. | G8: Arbetstidsförkortning m.m.
A9: =A61 -> 44561 | B9: =januari!I1 -> 144 | C9: =januari!B$4 -> 1 | D9: =IF(januari!$F$3=0,"",Saldo_jan) -> 2 | E9: =IF(D9="","",UB_jan) -> 8 | F9: =IF(januari!$F$4=0,"",januari!$F$4) | G9: =IF(D61="","",D61) -> Klämdag 2/1, 8 tim. Klämdag 5/1, 8 tim
A10: =A62 -> 44592 | B10: =februari!I1 -> 160 | C10: =februari!B$4 -> 1 | D10: =IF(februari!$F$3=0,"",Saldo_feb) -> 5.5 | E10: =IF(D10="","",UB_feb) -> 13.5 | F10: =IF(februari!$F$4=0,"",februari!$F$4) | G10: =IF(D62="","",D62)
A11: =A63 -> 44620 | B11: =mars!I1 -> 176 | C11: =mars!B$4 -> 1 | D11: =IF(mars!$F$3=0,"",Saldo_mar) -> -32.5 | E11: =IF(D11="","",UB_mar) -> 19.5 | F11: =IF(mars!$F$4=0,"",mars!$F$4) | G11: =IF(D63="","",D63)
A12: =A64 -> 44651 | B12: =april!I1 -> 160 | C12: =april!B$4 -> 1 | D12: =IF(april!$F$3=0,"",Saldo_apr) | E12: =IF(D12="","",UB_apr) | F12: =IF(april!$F$4=0,"",april!$F$4) | G12: =IF(D64="","",D64) -> Långfredagen 3/4, 8 tim. Annandag påsk 6/4, 8 tim
A13: =A65 -> 44681 | B13: =maj!I1 -> 144 | C13: =maj!B$4 -> 1 | D13: =IF(maj!$F$3=0,"",Saldo_maj) | E13: =IF(D13="","",UB_maj) | F13: =IF(maj!$F$4=0,"",maj!$F$4) | G13: =IF(D65="","",D65) -> Första maj 1/5, 8 tim. Kristi himmelsfärdsdag 14/5, 8 tim. Klämdag 15/5, 8 tim
A14: =A66 -> 44712 | B14: =juni!I1 -> 168 | C14: =juni!B$4 -> 1 | D14: =IF(juni!$F$3=0,"",Saldo_jun) | E14: =IF(D14="","",UB_jun) | F14: =IF(juni!$F$4=0,"",juni!$F$4) | G14: =IF(D66="","",D66) -> Midsommarafton 19/6, 8 tim
A15: =A67 -> 44742 | B15: =juli!I1 -> 184 | C15: =juli!B$4 -> 1 | D15: =IF(juli!$F$3=0,"",Saldo_jul) | E15: =IF(D15="","",UB_jul) | F15: =IF(juli!$F$4=0,"",juli!$F$4) | G15: =IF(D67="","",D67)
A16: =A68 -> 44773 | B16: =augusti!I1 -> 168 | C16: =augusti!B$4 -> 1 | D16: =IF(augusti!$F$3=0,"",Saldo_aug) | E16: =IF(D16="","",UB_aug) | F16: =IF(augusti!$F$4=0,"",augusti!$F$4) | G16: =IF(D68="","",D68)
A17: =A69 -> 44804 | B17: =september!I1 -> 176 | C17: =september!B$4 -> 1 | D17: =IF(september!$F$3=0,"",Saldo_sep) | E17: =IF(D17="","",UB_sep) | F17: =IF(september!$F$4=0,"",september!$F$4) | G17: =IF(D69="","",D69)
A18: =A70 -> 44834 | B18: =oktober!I1 -> 176 | C18: =oktober!B$4 -> 1 | D18: =IF(oktober!$F$3=0,"",Saldo_okt) | E18: =IF(D18="","",UB_okt) | F18: =IF(oktober!$F$4=0,"",oktober!$F$4) | G18: =IF(D70="","",D70)
A19: =A71 -> 44865 | B19: =november!I1 -> 168 | C19: =november!B$4 -> 1 | D19: =IF(november!$F$3=0,"",Saldo_nov) | E19: =IF(D19="","",UB_nov) | F19: =IF(november!$F$4=0,"",november!$F$4) | G19: =IF(D71="","",D71)
A20: =A72 -> 44895 | B20: =december!I1 -> 160 | C20: =december!B$4 -> 1 | D20: =IF(december!$F$3=0,"",Saldo_dec) | E20: =IF(D20="","",UB_dec) | F20: =IF(december!$F$4=0,"",december!$F$4) | G20: =IF(D72="","",D72) -> Julafton 24/12, 8 tim. Juldagen 25/12, 8 tim. Nyårsafton 31/12, 8 tim
A32: Version 4.6 © LiU 2025-12-03
A33: =TODAY() -> 44643
A59: Endast för blankettadministratören • här anges referenstider för heltidsarbetande
A60: Månad | B60: Arb dgr | C60: Ref tid | D60: Förkortning
A61: 44561 | B61: 18 | C61: 144 | D61: Klämdag 2/1, 8 tim. Klämdag 5/1, 8 tim
A62: 44592 | B62: 20 | C62: 160
A63: 44620 | B63: 22 | C63: 176
A64: 44651 | B64: 20 | C64: 160 | D64: Långfredagen 3/4, 8 tim. Annandag påsk 6/4, 8 tim
A65: 44681 | B65: 18 | C65: 144 | D65: Första maj 1/5, 8 tim. Kristi himmelsfärdsdag 14/5, 8 tim. Klämdag 15/5, 8 tim
A66: 44712 | B66: 21 | C66: 168 | D66: Midsommarafton 19/6, 8 tim
A67: 44742 | B67: 23 | C67: 184
A68: 44773 | B68: 21 | C68: 168
A69: 44804 | B69: 22 | C69: 176
A70: 44834 | B70: 22 | C70: 176
A71: 44865 | B71: 21 | C71: 168
A72: 44895 | B72: 20 | C72: 160 | D72: Julafton 24/12, 8 tim. Juldagen 25/12, 8 tim. Nyårsafton 31/12, 8 tim

Sheet januari
A1: Namn | B1: =Namn -> Håkan Stensby | E1: Närvaro | F1: =SUM(F7:F37) -> 146 | H1: Referenstid | I1: =VLOOKUP(B3,översikt!A61:C72,3,FALSE)*B4 -> 144
A2: Pnr | B2: =Pnr -> 19770217-6418 | E2: Avvikelse | F2: =VALUE(SUM(M7:M37)*24) -> 0 | H2: Månadens saldo | I2: =IF(F3=0,0,F3-I1) -> 2
A3: Månad | B3: =översikt!A61 -> 44561 | E3: Totalt | F3: =F1+F2 -> 146 | H3: Ing flex | I3: =översikt!B5 -> 6
A4: Tj-grad | B4: =Tjgrad -> 1 | E4: Ev korrigering | H4: Utg flex | I4: =IF(N7="", "-", OFFSET(N6, COUNT(N:N), 0, 1, 1) + I3) -> 8 | P4: För registrering av tid enligt egna uppdelningar.
B5: Närvarotid | J5: Avvikelser från dagregistreringen | N5: Saldo | P5: (Påverkar inte flextidsredovisningen.) | U5: Dag | V5: Norm | W5: Arb tim ack
A6: Dag | B6: Börjar | C6: Slutar | D6: Lunch | E6: Tim : min | F6: Tim dec | G6: Kommentar | J6: Fr.o.m. kl | K6: T.o.m. kl | L6: + / - | M6: Avvik tim | N6: hittills | O6: Noteringar
A7: =B3 -> 44561 | D7: =IF(C7="","",0.5/24) | E7: =IF(C7="",0,C7-B7-D7) -> 0 | F7: =IF(E7="","",VALUE(E7)*24) -> 0 | G7: Nyårsdagen | M7: =IF(OR(G7="Semester",G7="Sjuk",G7="Vård av barn"),8/24*$B$4,IF(L7="+",K7-J7,IF(L7="-",(K7-J7)*-1,0))) -> 0 | N7: =IF(Dagen>A7,W7-V7,"") -> 0 | U7: 8 | V7: =IF(U7>4,V6,V6+$B$4*8) -> 0 | W7: =VALUE(E7)*24+VALUE(M7)*24+W6 -> 0
A8: =A7+1 -> 44562 | D8: =IF(C8="","",0.5/24) | E8: =IF(C8="",0,C8-B8-D8) -> 0 | F8: =IF(E8="","",VALUE(E8)*24) -> 0 | G8: Klämdag! | M8: =IF(OR(G8="Semester",G8="Sjuk",G8="Vård av barn"),8/24*$B$4,IF(L8="+",K8-J8,IF(L8="-",(K8-J8)*-1,0))) -> 0 | N8: =IF(Dagen>A8,W8-V8,"") -> 0 | U8: 8 | V8: =IF(U8>4,V7,V7+$B$4*8) -> 0 | W8: =VALUE(E8)*24+VALUE(M8)*24+W7 -> 0
A9: =A8+1 -> 44563 | D9: =IF(C9="","",0.5/24) | E9: =IF(C9="",0,C9-B9-D9) -> 0 | F9: =IF(E9="","",VALUE(E9)*24) -> 0 | M9: =IF(OR(G9="Semester",G9="Sjuk",G9="Vård av barn"),8/24*$B$4,IF(L9="+",K9-J9,IF(L9="-",(K9-J9)*-1,0))) -> 0 | N9: =IF(Dagen>A9,W9-V9,"") -> 0 | U9: =IF(A9="",0,WEEKDAY(A9,3)) -> 5 | V9: =IF(U9>4,V8,V8+$B$4*8) -> 0 | W9: =VALUE(E9)*24+VALUE(M9)*24+W8 -> 0
A10: =A9+1 -> 44564 | D10: =IF(C10="","",0.5/24) | E10: =IF(C10="",0,C10-B10-D10) -> 0 | F10: =IF(E10="","",VALUE(E10)*24) -> 0 | M10: =IF(OR(G10="Semester",G10="Sjuk",G10="Vård av barn"),8/24*$B$4,IF(L10="+",K10-J10,IF(L10="-",(K10-J10)*-1,0))) -> 0 | N10: =IF(Dagen>A10,W10-V10,"") -> 0 | U10: =IF(A10="",0,WEEKDAY(A10,3)) -> 6 | V10: =IF(U10>4,V9,V9+$B$4*8) -> 0 | W10: =VALUE(E10)*24+VALUE(M10)*24+W9 -> 0
A11: =A10+1 -> 44565 | D11: =IF(C11="","",0.5/24) | E11: =IF(C11="",0,C11-B11-D11) -> 0 | F11: =IF(E11="","",VALUE(E11)*24) -> 0 | G11: Klämdag! | M11: =IF(OR(G11="Semester",G11="Sjuk",G11="Vård av barn"),8/24*$B$4,IF(L11="+",K11-J11,IF(L11="-",(K11-J11)*-1,0))) -> 0 | N11: =IF(Dagen>A11,W11-V11,"") -> 0 | U11: 8 | V11: =IF(U11>4,V10,V10+$B$4*4) -> 0 | W11: =VALUE(E11)*24+VALUE(M11)*24+W10 -> 0
A12: =A11+1 -> 44566 | D12: =IF(C12="","",0.5/24) | E12: =IF(C12="",0,C12-B12-D12) -> 0 | F12: =IF(E12="","",VALUE(E12)*24) -> 0 | G12: Trettondedag jul | M12: =IF(OR(G12="Semester",G12="Sjuk",G12="Vård av barn"),8/24*$B$4,IF(L12="+",K12-J12,IF(L12="-",(K12-J12)*-1,0))) -> 0 | N12: =IF(Dagen>A12,W12-V12,"") -> 0 | U12: 8 | V12: =IF(U12>4,V11,V11+$B$4*8) -> 0 | W12: =VALUE(E12)*24+VALUE(M12)*24+W11 -> 0
A13: =A12+1 -> 44567 | B13: 0.29166667 | C13: 0.64583333 | D13: =IF(C13="","",0.5/24) -> 0.020833333 | E13: =IF(C13="",0,C13-B13-D13) -> 0.33333333 | F13: =IF(E13="","",VALUE(E13)*24) -> 8 | M13: =IF(OR(G13="Semester",G13="Sjuk",G13="Vård av barn"),8/24*$B$4,IF(L13="+",K13-J13,IF(L13="-",(K13-J13)*-1,0))) -> 0 | N13: =IF(Dagen>A13,W13-V13,"") -> 0 | U13: =IF(A13="",0,WEEKDAY(A13,3)) -> 2 | V13: =IF(U13>4,V12,V12+$B$4*8) -> 8 | W13: =VALUE(E13)*24+VALUE(M13)*24+W12 -> 8
A14: =A13+1 -> 44568 | B14: 0.29166667 | C14: 0.64583333 | D14: =IF(C14="","",0.5/24) -> 0.020833333 | E14: =IF(C14="",0,C14-B14-D14) -> 0.33333333 | F14: =IF(E14="","",VALUE(E14)*24) -> 8 | M14: =IF(OR(G14="Semester",G14="Sjuk",G14="Vård av barn"),8/24*$B$4,IF(L14="+",K14-J14,IF(L14="-",(K14-J14)*-1,0))) -> 0 | N14: =IF(Dagen>A14,W14-V14,"") -> 0 | U14: =IF(A14="",0,WEEKDAY(A14,3)) -> 3 | V14: =IF(U14>4,V13,V13+$B$4*8) -> 16 | W14: =VALUE(E14)*24+VALUE(M14)*24+W13 -> 16
A15: =A14+1 -> 44569 | B15: 0.29166667 | C15: 0.64583333 | D15: =IF(C15="","",0.5/24) -> 0.020833333 | E15: =IF(C15="",0,C15-B15-D15) -> 0.33333333 | F15: =IF(E15="","",VALUE(E15)*24) -> 8 | M15: =IF(OR(G15="Semester",G15="Sjuk",G15="Vård av barn"),8/24*$B$4,IF(L15="+",K15-J15,IF(L15="-",(K15-J15)*-1,0))) -> 0 | N15: =IF(Dagen>A15,W15-V15,"") -> 0 | U15: =IF(A15="",0,WEEKDAY(A15,3)) -> 4 | V15: =IF(U15>4,V14,V14+$B$4*8) -> 24 | W15: =VALUE(E15)*24+VALUE(M15)*24+W14 -> 24
A16: =A15+1 -> 44570 | D16: =IF(C16="","",0.5/24) | E16: =IF(C16="",0,C16-B16-D16) -> 0 | F16: =IF(E16="","",VALUE(E16)*24) -> 0 | M16: =IF(OR(G16="Semester",G16="Sjuk",G16="Vård av barn"),8/24*$B$4,IF(L16="+",K16-J16,IF(L16="-",(K16-J16)*-1,0))) -> 0 | N16: =IF(Dagen>A16,W16-V16,"") -> 0 | U16: =IF(A16="",0,WEEKDAY(A16,3)) -> 5 | V16: =IF(U16>4,V15,V15+$B$4*8) -> 24 | W16: =VALUE(E16)*24+VALUE(M16)*24+W15 -> 24
A17: =A16+1 -> 44571 | D17: =IF(C17="","",0.5/24) | E17: =IF(C17="",0,C17-B17-D17) -> 0 | F17: =IF(E17="","",VALUE(E17)*24) -> 0 | M17: =IF(OR(G17="Semester",G17="Sjuk",G17="Vård av barn"),8/24*$B$4,IF(L17="+",K17-J17,IF(L17="-",(K17-J17)*-1,0))) -> 0 | N17: =IF(Dagen>A17,W17-V17,"") -> 0 | U17: =IF(A17="",0,WEEKDAY(A17,3)) -> 6 | V17: =IF(U17>4,V16,V16+$B$4*8) -> 24 | W17: =VALUE(E17)*24+VALUE(M17)*24+W16 -> 24
A18: =A17+1 -> 44572 | B18: 0.29166667 | C18: 0.64583333 | D18: =IF(C18="","",0.5/24) -> 0.020833333 | E18: =IF(C18="",0,C18-B18-D18) -> 0.33333333 | F18: =IF(E18="","",VALUE(E18)*24) -> 8 | M18: =IF(OR(G18="Semester",G18="Sjuk",G18="Vård av barn"),8/24*$B$4,IF(L18="+",K18-J18,IF(L18="-",(K18-J18)*-1,0))) -> 0 | N18: =IF(Dagen>A18,W18-V18,"") -> 0 | U18: =IF(A18="",0,WEEKDAY(A18,3)) -> 0 | V18: =IF(U18>4,V17,V17+$B$4*8) -> 32 | W18: =VALUE(E18)*24+VALUE(M18)*24+W17 -> 32
A19: =A18+1 -> 44573 | B19: 0.29166667 | C19: 0.66666667 | D19: =IF(C19="","",0.5/24) -> 0.020833333 | E19: =IF(C19="",0,C19-B19-D19) -> 0.35416667 | F19: =IF(E19="","",VALUE(E19)*24) -> 8.5 | M19: =IF(OR(G19="Semester",G19="Sjuk",G19="Vård av barn"),8/24*$B$4,IF(L19="+",K19-J19,IF(L19="-",(K19-J19)*-1,0))) -> 0 | N19: =IF(Dagen>A19,W19-V19,"") -> 0.5 | U19: =IF(A19="",0,WEEKDAY(A19,3)) -> 1 | V19: =IF(U19>4,V18,V18+$B$4*8) -> 40 | W19: =VALUE(E19)*24+VALUE(M19)*24+W18 -> 40.5
A20: =A19+1 -> 44574 | B20: 0.29166667 | C20: 0.64583333 | D20: =IF(C20="","",0.5/24) -> 0.020833333 | E20: =IF(C20="",0,C20-B20-D20) -> 0.33333333 | F20: =IF(E20="","",VALUE(E20)*24) -> 8 | M20: =IF(OR(G20="Semester",G20="Sjuk",G20="Vård av barn"),8/24*$B$4,IF(L20="+",K20-J20,IF(L20="-",(K20-J20)*-1,0))) -> 0 | N20: =IF(Dagen>A20,W20-V20,"") -> 0.5 | U20: =IF(A20="",0,WEEKDAY(A20,3)) -> 2 | V20: =IF(U20>4,V19,V19+$B$4*8) -> 48 | W20: =VALUE(E20)*24+VALUE(M20)*24+W19 -> 48.5
A21: =A20+1 -> 44575 | B21: 0.29166667 | C21: 0.66666667 | D21: =IF(C21="","",0.5/24) -> 0.020833333 | E21: =IF(C21="",0,C21-B21-D21) -> 0.35416667 | F21: =IF(E21="","",VALUE(E21)*24) -> 8.5 | M21: =IF(OR(G21="Semester",G21="Sjuk",G21="Vård av barn"),8/24*$B$4,IF(L21="+",K21-J21,IF(L21="-",(K21-J21)*-1,0))) -> 0 | N21: =IF(Dagen>A21,W21-V21,"") -> 1 | U21: =IF(A21="",0,WEEKDAY(A21,3)) -> 3 | V21: =IF(U21>4,V20,V20+$B$4*8) -> 56 | W21: =VALUE(E21)*24+VALUE(M21)*24+W20 -> 57
A22: =A21+1 -> 44576 | B22: 0.29166667 | C22: 0.64583333 | D22: =IF(C22="","",0.5/24) -> 0.020833333 | E22: =IF(C22="",0,C22-B22-D22) -> 0.33333333 | F22: =IF(E22="","",VALUE(E22)*24) -> 8 | M22: =IF(OR(G22="Semester",G22="Sjuk",G22="Vård av barn"),8/24*$B$4,IF(L22="+",K22-J22,IF(L22="-",(K22-J22)*-1,0))) -> 0 | N22: =IF(Dagen>A22,W22-V22,"") -> 1 | U22: =IF(A22="",0,WEEKDAY(A22,3)) -> 4 | V22: =IF(U22>4,V21,V21+$B$4*8) -> 64 | W22: =VALUE(E22)*24+VALUE(M22)*24+W21 -> 65
A23: =A22+1 -> 44577 | D23: =IF(C23="","",0.5/24) | E23: =IF(C23="",0,C23-B23-D23) -> 0 | F23: =IF(E23="","",VALUE(E23)*24) -> 0 | M23: =IF(OR(G23="Semester",G23="Sjuk",G23="Vård av barn"),8/24*$B$4,IF(L23="+",K23-J23,IF(L23="-",(K23-J23)*-1,0))) -> 0 | N23: =IF(Dagen>A23,W23-V23,"") -> 1 | U23: =IF(A23="",0,WEEKDAY(A23,3)) -> 5 | V23: =IF(U23>4,V22,V22+$B$4*8) -> 64 | W23: =VALUE(E23)*24+VALUE(M23)*24+W22 -> 65
A24: =A23+1 -> 44578 | D24: =IF(C24="","",0.5/24) | E24: =IF(C24="",0,C24-B24-D24) -> 0 | F24: =IF(E24="","",VALUE(E24)*24) -> 0 | M24: =IF(OR(G24="Semester",G24="Sjuk",G24="Vård av barn"),8/24*$B$4,IF(L24="+",K24-J24,IF(L24="-",(K24-J24)*-1,0))) -> 0 | N24: =IF(Dagen>A24,W24-V24,"") -> 1 | U24: =IF(A24="",0,WEEKDAY(A24,3)) -> 6 | V24: =IF(U24>4,V23,V23+$B$4*8) -> 64 | W24: =VALUE(E24)*24+VALUE(M24)*24+W23 -> 65
A25: =A24+1 -> 44579 | B25: 0.29166667 | C25: 0.66666667 | D25: =IF(C25="","",0.5/24) -> 0.020833333 | E25: =IF(C25="",0,C25-B25-D25) -> 0.35416667 | F25: =IF(E25="","",VALUE(E25)*24) -> 8.5 | M25: =IF(OR(G25="Semester",G25="Sjuk",G25="Vård av barn"),8/24*$B$4,IF(L25="+",K25-J25,IF(L25="-",(K25-J25)*-1,0))) -> 0 | N25: =IF(Dagen>A25,W25-V25,"") -> 1.5 | U25: =IF(A25="",0,WEEKDAY(A25,3)) -> 0 | V25: =IF(U25>4,V24,V24+$B$4*8) -> 72 | W25: =VALUE(E25)*24+VALUE(M25)*24+W24 -> 73.5
A26: =A25+1 -> 44580 | B26: 0.29166667 | C26: 0.66666667 | D26: =IF(C26="","",0.5/24) -> 0.020833333 | E26: =IF(C26="",0,C26-B26-D26) -> 0.35416667 | F26: =IF(E26="","",VALUE(E26)*24) -> 8.5 | M26: =IF(OR(G26="Semester",G26="Sjuk",G26="Vård av barn"),8/24*$B$4,IF(L26="+",K26-J26,IF(L26="-",(K26-J26)*-1,0))) -> 0 | N26: =IF(Dagen>A26,W26-V26,"") -> 2 | U26: =IF(A26="",0,WEEKDAY(A26,3)) -> 1 | V26: =IF(U26>4,V25,V25+$B$4*8) -> 80 | W26: =VALUE(E26)*24+VALUE(M26)*24+W25 -> 82
A27: =A26+1 -> 44581 | B27: 0.29166667 | C27: 0.64583333 | D27: =IF(C27="","",0.5/24) -> 0.020833333 | E27: =IF(C27="",0,C27-B27-D27) -> 0.33333333 | F27: =IF(E27="","",VALUE(E27)*24) -> 8 | M27: =IF(OR(G27="Semester",G27="Sjuk",G27="Vård av barn"),8/24*$B$4,IF(L27="+",K27-J27,IF(L27="-",(K27-J27)*-1,0))) -> 0 | N27: =IF(Dagen>A27,W27-V27,"") -> 2 | U27: =IF(A27="",0,WEEKDAY(A27,3)) -> 2 | V27: =IF(U27>4,V26,V26+$B$4*8) -> 88 | W27: =VALUE(E27)*24+VALUE(M27)*24+W26 -> 90
A28: =A27+1 -> 44582 | B28: 0.29166667 | C28: 0.64583333 | D28: =IF(C28="","",0.5/24) -> 0.020833333 | E28: =IF(C28="",0,C28-B28-D28) -> 0.33333333 | F28: =IF(E28="","",VALUE(E28)*24) -> 8 | M28: =IF(OR(G28="Semester",G28="Sjuk",G28="Vård av barn"),8/24*$B$4,IF(L28="+",K28-J28,IF(L28="-",(K28-J28)*-1,0))) -> 0 | N28: =IF(Dagen>A28,W28-V28,"") -> 2 | U28: =IF(A28="",0,WEEKDAY(A28,3)) -> 3 | V28: =IF(U28>4,V27,V27+$B$4*8) -> 96 | W28: =VALUE(E28)*24+VALUE(M28)*24+W27 -> 98
A29: =A28+1 -> 44583 | B29: 0.29166667 | C29: 0.64583333 | D29: =IF(C29="","",0.5/24) -> 0.020833333 | E29: =IF(C29="",0,C29-B29-D29) -> 0.33333333 | F29: =IF(E29="","",VALUE(E29)*24) -> 8 | M29: =IF(OR(G29="Semester",G29="Sjuk",G29="Vård av barn"),8/24*$B$4,IF(L29="+",K29-J29,IF(L29="-",(K29-J29)*-1,0))) -> 0 | N29: =IF(Dagen>A29,W29-V29,"") -> 2 | U29: =IF(A29="",0,WEEKDAY(A29,3)) -> 4 | V29: =IF(U29>4,V28,V28+$B$4*8) -> 104 | W29: =VALUE(E29)*24+VALUE(M29)*24+W28 -> 106
A30: =A29+1 -> 44584 | D30: =IF(C30="","",0.5/24) | E30: =IF(C30="",0,C30-B30-D30) -> 0 | F30: =IF(E30="","",VALUE(E30)*24) -> 0 | M30: =IF(OR(G30="Semester",G30="Sjuk",G30="Vård av barn"),8/24*$B$4,IF(L30="+",K30-J30,IF(L30="-",(K30-J30)*-1,0))) -> 0 | N30: =IF(Dagen>A30,W30-V30,"") -> 2 | U30: =IF(A30="",0,WEEKDAY(A30,3)) -> 5 | V30: =IF(U30>4,V29,V29+$B$4*8) -> 104 | W30: =VALUE(E30)*24+VALUE(M30)*24+W29 -> 106
A31: =A30+1 -> 44585 | D31: =IF(C31="","",0.5/24) | E31: =IF(C31="",0,C31-B31-D31) -> 0 | F31: =IF(E31="","",VALUE(E31)*24) -> 0 | M31: =IF(OR(G31="Semester",G31="Sjuk",G31="Vård av barn"),8/24*$B$4,IF(L31="+",K31-J31,IF(L31="-",(K31-J31)*-1,0))) -> 0 | N31: =IF(Dagen>A31,W31-V31,"") -> 2 | U31: =IF(A31="",0,WEEKDAY(A31,3)) -> 6 | V31: =IF(U31>4,V30,V30+$B$4*8) -> 104 | W31: =VALUE(E31)*24+VALUE(M31)*24+W30 -> 106
A32: =A31+1 -> 44586 | B32: 0.29166667 | C32: 0.64583333 | D32: =IF(C32="","",0.5/24) -> 0.020833333 | E32: =IF(C32="",0,C32-B32-D32) -> 0.33333333 | F32: =IF(E32="","",VALUE(E32)*24) -> 8 | M32: =IF(OR(G32="Semester",G32="Sjuk",G32="Vård av barn"),8/24*$B$4,IF(L32="+",K32-J32,IF(L32="-",(K32-J32)*-1,0))) -> 0 | N32: =IF(Dagen>A32,W32-V32,"") -> 2 | U32: =IF(A32="",0,WEEKDAY(A32,3)) -> 0 | V32: =IF(U32>4,V31,V31+$B$4*8) -> 112 | W32: =VALUE(E32)*24+VALUE(M32)*24+W31 -> 114
A33: =A32+1 -> 44587 | B33: 0.29166667 | C33: 0.64583333 | D33: =IF(C33="","",0.5/24) -> 0.020833333 | E33: =IF(C33="",0,C33-B33-D33) -> 0.33333333 | F33: =IF(E33="","",VALUE(E33)*24) -> 8 | M33: =IF(OR(G33="Semester",G33="Sjuk",G33="Vård av barn"),8/24*$B$4,IF(L33="+",K33-J33,IF(L33="-",(K33-J33)*-1,0))) -> 0 | N33: =IF(Dagen>A33,W33-V33,"") -> 2 | U33: =IF(A33="",0,WEEKDAY(A33,3)) -> 1 | V33: =IF(U33>4,V32,V32+$B$4*8) -> 120 | W33: =VALUE(E33)*24+VALUE(M33)*24+W32 -> 122
A34: =A33+1 -> 44588 | B34: 0.29166667 | C34: 0.64583333 | D34: =IF(C34="","",0.5/24) -> 0.020833333 | E34: =IF(C34="",0,C34-B34-D34) -> 0.33333333 | F34: =IF(E34="","",VALUE(E34)*24) -> 8 | M34: =IF(OR(G34="Semester",G34="Sjuk",G34="Vård av barn"),8/24*$B$4,IF(L34="+",K34-J34,IF(L34="-",(K34-J34)*-1,0))) -> 0 | N34: =IF(Dagen>A34,W34-V34,"") -> 2 | U34: =IF(A34="",0,WEEKDAY(A34,3)) -> 2 | V34: =IF(U34>4,V33,V33+$B$4*8) -> 128 | W34: =VALUE(E34)*24+VALUE(M34)*24+W33 -> 130
A35: =A34+1 -> 44589 | B35: 0.29166667 | C35: 0.64583333 | D35: =IF(C35="","",0.5/24) -> 0.020833333 | E35: =IF(C35="",0,C35-B35-D35) -> 0.33333333 | F35: =IF(E35="","",VALUE(E35)*24) -> 8 | M35: =IF(OR(G35="Semester",G35="Sjuk",G35="Vård av barn"),8/24*$B$4,IF(L35="+",K35-J35,IF(L35="-",(K35-J35)*-1,0))) -> 0 | N35: =IF(Dagen>A35,W35-V35,"") -> 2 | U35: =IF(A35="",0,WEEKDAY(A35,3)) -> 3 | V35: =IF(U35>4,V34,V34+$B$4*8) -> 136 | W35: =VALUE(E35)*24+VALUE(M35)*24+W34 -> 138
A36: =A35+1 -> 44590 | B36: 0.29166667 | C36: 0.64583333 | D36: =IF(C36="","",0.5/24) -> 0.020833333 | E36: =IF(C36="",0,C36-B36-D36) -> 0.33333333 | F36: =IF(E36="","",VALUE(E36)*24) -> 8 | M36: =IF(OR(G36="Semester",G36="Sjuk",G36="Vård av barn"),8/24*$B$4,IF(L36="+",K36-J36,IF(L36="-",(K36-J36)*-1,0))) -> 0 | N36: =IF(Dagen>A36,W36-V36,"") -> 2 | U36: =IF(A36="",0,WEEKDAY(A36,3)) -> 4 | V36: =IF(U36>4,V35,V35+$B$4*8) -> 144 | W36: =VALUE(E36)*24+VALUE(M36)*24+W35 -> 146
A37: =A36+1 -> 44591 | D37: =IF(C37="","",0.5/24) | E37: =IF(C37="",0,C37-B37-D37) -> 0 | F37: =IF(E37="","",VALUE(E37)*24) -> 0 | M37: =IF(OR(G37="Semester",G37="Sjuk",G37="Vård av barn"),8/24*$B$4,IF(L37="+",K37-J37,IF(L37="-",(K37-J37)*-1,0))) -> 0 | N37: =IF(Dagen>A37,W37-V37,"") -> 2 | U37: =IF(A37="",0,WEEKDAY(A37,3)) -> 5 | V37: =IF(U37>4,V36,V36+$B$4*8) -> 144 | W37: =VALUE(E37)*24+VALUE(M37)*24+W36 -> 146
P38: =SUM(P7:P37) -> 0 | Q38: =SUM(Q7:Q37) -> 0 | R38: =SUM(R7:R37) -> 0 | S38: =SUM(S7:S37) -> 0 | T38: =SUM(T7:T37) -> 0
A40: =Blankettinfo -> Version 4.6 © LiU 2025-12-03

Sheet februari
A1: Namn | B1: =Namn -> Håkan Stensby | E1: Närvaro | F1: =SUM(F7:F37) -> 157.5 | H1: Referenstid | I1: =VLOOKUP(B3,översikt!A61:C72,3,FALSE)*B4 -> 160
A2: Pnr | B2: =Pnr -> 19770217-6418 | E2: Avvikelse | F2: =VALUE(SUM(M7:M37)*24) -> 8 | H2: Månadens saldo | I2: =IF(F3=0,0,F3-I1) -> 5.5
A3: Månad | B3: =översikt!A62 -> 44592 | E3: Totalt | F3: =F1+F2 -> 165.5 | H3: Ing flex | I3: =januari!I4 -> 8
A4: Tj-grad | B4: =Tjgrad -> 1 | D4: Ev korrigering | H4: Utg flex | I4: =IF(N7="", "-", OFFSET(N6, COUNT(N:N), 0, 1, 1) + I3) -> 13.5 | P4: För registrering av tid enligt egna uppdelningar.
B5: Närvarotid | J5: Avvikelser från dagregistreringen | N5: Saldo | P5: (Påverkar inte flextidsredovisningen.) | U5: Dag | V5: Norm | W5: Arb tim ack
A6: Dag | B6: Börjar | C6: Slutar | D6: Lunch | E6: Tim : min | F6: Tim dec | G6: Kommentar | J6: Fr.o.m. kl | K6: T.o.m. kl | L6: + / - | M6: Avvik tim | N6: hittills | O6: Noteringar
A7: =B3 -> 44592 | D7: =IF(C7="","",0.5/24) | E7: =IF(C7="",0,C7-B7-D7) -> 0 | F7: =IF(E7="","",VALUE(E7)*24) -> 0 | M7: =IF(OR(G7="Semester",G7="Sjuk",G7="Vård av barn"),8/24*$B$4,IF(L7="+",K7-J7,IF(L7="-",(K7-J7)*-1,0))) -> 0 | N7: =IF(Dagen>A7,W7-V7,"") -> 0 | U7: =IF(A7="",0,WEEKDAY(A7,3)) -> 6 | V7: =IF(U7>4,V6,V6+$B$4*8) -> 0 | W7: =VALUE(E7)*24+VALUE(M7)*24+W6 -> 0
A8: =A7+1 -> 44593 | B8: 0.29166667 | C8: 0.66666667 | D8: =IF(C8="","",0.5/24) -> 0.020833333 | E8: =IF(C8="",0,C8-B8-D8) -> 0.35416667 | F8: =IF(E8="","",VALUE(E8)*24) -> 8.5 | M8: =IF(OR(G8="Semester",G8="Sjuk",G8="Vård av barn"),8/24*$B$4,IF(L8="+",K8-J8,IF(L8="-",(K8-J8)*-1,0))) -> 0 | N8: =IF(Dagen>A8,W8-V8,"") -> 0.5 | U8: =IF(A8="",0,WEEKDAY(A8,3)) -> 0 | V8: =IF(U8>4,V7,V7+$B$4*8) -> 8 | W8: =VALUE(E8)*24+VALUE(M8)*24+W7 -> 8.5
A9: =A8+1 -> 44594 | B9: 0.29166667 | C9: 0.66666667 | D9: =IF(C9="","",0.5/24) -> 0.020833333 | E9: =IF(C9="",0,C9-B9-D9) -> 0.35416667 | F9: =IF(E9="","",VALUE(E9)*24) -> 8.5 | M9: =IF(OR(G9="Semester",G9="Sjuk",G9="Vård av barn"),8/24*$B$4,IF(L9="+",K9-J9,IF(L9="-",(K9-J9)*-1,0))) -> 0 | N9: =IF(Dagen>A9,W9-V9,"") -> 1 | U9: =IF(A9="",0,WEEKDAY(A9,3)) -> 1 | V9: =IF(U9>4,V8,V8+$B$4*8) -> 16 | W9: =VALUE(E9)*24+VALUE(M9)*24+W8 -> 17
A10: =A9+1 -> 44595 | B10: 0.29166667 | C10: 0.66666667 | D10: =IF(C10="","",0.5/24) -> 0.020833333 | E10: =IF(C10="",0,C10-B10-D10) -> 0.35416667 | F10: =IF(E10="","",VALUE(E10)*24) -> 8.5 | M10: =IF(OR(G10="Semester",G10="Sjuk",G10="Vård av barn"),8/24*$B$4,IF(L10="+",K10-J10,IF(L10="-",(K10-J10)*-1,0))) -> 0 | N10: =IF(Dagen>A10,W10-V10,"") -> 1.5 | U10: =IF(A10="",0,WEEKDAY(A10,3)) -> 2 | V10: =IF(U10>4,V9,V9+$B$4*8) -> 24 | W10: =VALUE(E10)*24+VALUE(M10)*24+W9 -> 25.5
A11: =A10+1 -> 44596 | B11: 0.29166667 | C11: 0.66666667 | D11: =IF(C11="","",0.5/24) -> 0.020833333 | E11: =IF(C11="",0,C11-B11-D11) -> 0.35416667 | F11: =IF(E11="","",VALUE(E11)*24) -> 8.5 | M11: =IF(OR(G11="Semester",G11="Sjuk",G11="Vård av barn"),8/24*$B$4,IF(L11="+",K11-J11,IF(L11="-",(K11-J11)*-1,0))) -> 0 | N11: =IF(Dagen>A11,W11-V11,"") -> 2 | U11: =IF(A11="",0,WEEKDAY(A11,3)) -> 3 | V11: =IF(U11>4,V10,V10+$B$4*8) -> 32 | W11: =VALUE(E11)*24+VALUE(M11)*24+W10 -> 34
A12: =A11+1 -> 44597 | B12: 0.29166667 | C12: 0.64583333 | D12: =IF(C12="","",0.5/24) -> 0.020833333 | E12: =IF(C12="",0,C12-B12-D12) -> 0.33333333 | F12: =IF(E12="","",VALUE(E12)*24) -> 8 | M12: =IF(OR(G12="Semester",G12="Sjuk",G12="Vård av barn"),8/24*$B$4,IF(L12="+",K12-J12,IF(L12="-",(K12-J12)*-1,0))) -> 0 | N12: =IF(Dagen>A12,W12-V12,"") -> 2 | U12: =IF(A12="",0,WEEKDAY(A12,3)) -> 4 | V12: =IF(U12>4,V11,V11+$B$4*8) -> 40 | W12: =VALUE(E12)*24+VALUE(M12)*24+W11 -> 42
A13: =A12+1 -> 44598 | D13: =IF(C13="","",0.5/24) | E13: =IF(C13="",0,C13-B13-D13) -> 0 | F13: =IF(E13="","",VALUE(E13)*24) -> 0 | M13: =IF(OR(G13="Semester",G13="Sjuk",G13="Vård av barn"),8/24*$B$4,IF(L13="+",K13-J13,IF(L13="-",(K13-J13)*-1,0))) -> 0 | N13: =IF(Dagen>A13,W13-V13,"") -> 2 | U13: =IF(A13="",0,WEEKDAY(A13,3)) -> 5 | V13: =IF(U13>4,V12,V12+$B$4*8) -> 40 | W13: =VALUE(E13)*24+VALUE(M13)*24+W12 -> 42
A14: =A13+1 -> 44599 | D14: =IF(C14="","",0.5/24) | E14: =IF(C14="",0,C14-B14-D14) -> 0 | F14: =IF(E14="","",VALUE(E14)*24) -> 0 | M14: =IF(OR(G14="Semester",G14="Sjuk",G14="Vård av barn"),8/24*$B$4,IF(L14="+",K14-J14,IF(L14="-",(K14-J14)*-1,0))) -> 0 | N14: =IF(Dagen>A14,W14-V14,"") -> 2 | U14: =IF(A14="",0,WEEKDAY(A14,3)) -> 6 | V14: =IF(U14>4,V13,V13+$B$4*8) -> 40 | W14: =VALUE(E14)*24+VALUE(M14)*24+W13 -> 42
A15: =A14+1 -> 44600 | B15: 0.29166667 | C15: 0.66666667 | D15: =IF(C15="","",0.5/24) -> 0.020833333 | E15: =IF(C15="",0,C15-B15-D15) -> 0.35416667 | F15: =IF(E15="","",VALUE(E15)*24) -> 8.5 | M15: =IF(OR(G15="Semester",G15="Sjuk",G15="Vård av barn"),8/24*$B$4,IF(L15="+",K15-J15,IF(L15="-",(K15-J15)*-1,0))) -> 0 | N15: =IF(Dagen>A15,W15-V15,"") -> 2.5 | U15: =IF(A15="",0,WEEKDAY(A15,3)) -> 0 | V15: =IF(U15>4,V14,V14+$B$4*8) -> 48 | W15: =VALUE(E15)*24+VALUE(M15)*24+W14 -> 50.5
A16: =A15+1 -> 44601 | B16: 0.29166667 | C16: 0.66666667 | D16: =IF(C16="","",0.5/24) -> 0.020833333 | E16: =IF(C16="",0,C16-B16-D16) -> 0.35416667 | F16: =IF(E16="","",VALUE(E16)*24) -> 8.5 | M16: =IF(OR(G16="Semester",G16="Sjuk",G16="Vård av barn"),8/24*$B$4,IF(L16="+",K16-J16,IF(L16="-",(K16-J16)*-1,0))) -> 0 | N16: =IF(Dagen>A16,W16-V16,"") -> 3 | U16: =IF(A16="",0,WEEKDAY(A16,3)) -> 1 | V16: =IF(U16>4,V15,V15+$B$4*8) -> 56 | W16: =VALUE(E16)*24+VALUE(M16)*24+W15 -> 59
A17: =A16+1 -> 44602 | B17: 0.29166667 | C17: 0.66666667 | D17: =IF(C17="","",0.5/24) -> 0.020833333 | E17: =IF(C17="",0,C17-B17-D17) -> 0.35416667 | F17: =IF(E17="","",VALUE(E17)*24) -> 8.5 | M17: =IF(OR(G17="Semester",G17="Sjuk",G17="Vård av barn"),8/24*$B$4,IF(L17="+",K17-J17,IF(L17="-",(K17-J17)*-1,0))) -> 0 | N17: =IF(Dagen>A17,W17-V17,"") -> 3.5 | U17: =IF(A17="",0,WEEKDAY(A17,3)) -> 2 | V17: =IF(U17>4,V16,V16+$B$4*8) -> 64 | W17: =VALUE(E17)*24+VALUE(M17)*24+W16 -> 67.5
A18: =A17+1 -> 44603 | B18: 0.29166667 | C18: 0.66666667 | D18: =IF(C18="","",0.5/24) -> 0.020833333 | E18: =IF(C18="",0,C18-B18-D18) -> 0.35416667 | F18: =IF(E18="","",VALUE(E18)*24) -> 8.5 | M18: =IF(OR(G18="Semester",G18="Sjuk",G18="Vård av barn"),8/24*$B$4,IF(L18="+",K18-J18,IF(L18="-",(K18-J18)*-1,0))) -> 0 | N18: =IF(Dagen>A18,W18-V18,"") -> 4 | U18: =IF(A18="",0,WEEKDAY(A18,3)) -> 3 | V18: =IF(U18>4,V17,V17+$B$4*8) -> 72 | W18: =VALUE(E18)*24+VALUE(M18)*24+W17 -> 76
A19: =A18+1 -> 44604 | B19: 0.29166667 | C19: 0.64583333 | D19: =IF(C19="","",0.5/24) -> 0.020833333 | E19: =IF(C19="",0,C19-B19-D19) -> 0.33333333 | F19: =IF(E19="","",VALUE(E19)*24) -> 8 | M19: =IF(OR(G19="Semester",G19="Sjuk",G19="Vård av barn"),8/24*$B$4,IF(L19="+",K19-J19,IF(L19="-",(K19-J19)*-1,0))) -> 0 | N19: =IF(Dagen>A19,W19-V19,"") -> 4 | U19: =IF(A19="",0,WEEKDAY(A19,3)) -> 4 | V19: =IF(U19>4,V18,V18+$B$4*8) -> 80 | W19: =VALUE(E19)*24+VALUE(M19)*24+W18 -> 84
A20: =A19+1 -> 44605 | D20: =IF(C20="","",0.5/24) | E20: =IF(C20="",0,C20-B20-D20) -> 0 | F20: =IF(E20="","",VALUE(E20)*24) -> 0 | M20: =IF(OR(G20="Semester",G20="Sjuk",G20="Vård av barn"),8/24*$B$4,IF(L20="+",K20-J20,IF(L20="-",(K20-J20)*-1,0))) -> 0 | N20: =IF(Dagen>A20,W20-V20,"") -> 4 | U20: =IF(A20="",0,WEEKDAY(A20,3)) -> 5 | V20: =IF(U20>4,V19,V19+$B$4*8) -> 80 | W20: =VALUE(E20)*24+VALUE(M20)*24+W19 -> 84
A21: =A20+1 -> 44606 | D21: =IF(C21="","",0.5/24) | E21: =IF(C21="",0,C21-B21-D21) -> 0 | F21: =IF(E21="","",VALUE(E21)*24) -> 0 | M21: =IF(OR(G21="Semester",G21="Sjuk",G21="Vård av barn"),8/24*$B$4,IF(L21="+",K21-J21,IF(L21="-",(K21-J21)*-1,0))) -> 0 | N21: =IF(Dagen>A21,W21-V21,"") -> 4 | U21: =IF(A21="",0,WEEKDAY(A21,3)) -> 6 | V21: =IF(U21>4,V20,V20+$B$4*8) -> 80 | W21: =VALUE(E21)*24+VALUE(M21)*24+W20 -> 84
A22: =A21+1 -> 44607 | B22: 0.29166667 | C22: 0.64583333 | D22: =IF(C22="","",0.5/24) -> 0.020833333 | E22: =IF(C22="",0,C22-B22-D22) -> 0.33333333 | F22: =IF(E22="","",VALUE(E22)*24) -> 8 | M22: =IF(OR(G22="Semester",G22="Sjuk",G22="Vård av barn"),8/24*$B$4,IF(L22="+",K22-J22,IF(L22="-",(K22-J22)*-1,0))) -> 0 | N22: =IF(Dagen>A22,W22-V22,"") -> 4 | U22: =IF(A22="",0,WEEKDAY(A22,3)) -> 0 | V22: =IF(U22>4,V21,V21+$B$4*8) -> 88 | W22: =VALUE(E22)*24+VALUE(M22)*24+W21 -> 92
A23: =A22+1 -> 44608 | B23: 0.29166667 | C23: 0.64583333 | D23: =IF(C23="","",0.5/24) -> 0.020833333 | E23: =IF(C23="",0,C23-B23-D23) -> 0.33333333 | F23: =IF(E23="","",VALUE(E23)*24) -> 8 | G23: Fettisdagen! | M23: =IF(OR(G23="Semester",G23="Sjuk",G23="Vård av barn"),8/24*$B$4,IF(L23="+",K23-J23,IF(L23="-",(K23-J23)*-1,0))) -> 0 | N23: =IF(Dagen>A23,W23-V23,"") -> 4 | U23: =IF(A23="",0,WEEKDAY(A23,3)) -> 1 | V23: =IF(U23>4,V22,V22+$B$4*8) -> 96 | W23: =VALUE(E23)*24+VALUE(M23)*24+W22 -> 100
A24: =A23+1 -> 44609 | B24: 0.29166667 | C24: 0.64583333 | D24: =IF(C24="","",0.5/24) -> 0.020833333 | E24: =IF(C24="",0,C24-B24-D24) -> 0.33333333 | F24: =IF(E24="","",VALUE(E24)*24) -> 8 | M24: =IF(OR(G24="Semester",G24="Sjuk",G24="Vård av barn"),8/24*$B$4,IF(L24="+",K24-J24,IF(L24="-",(K24-J24)*-1,0))) -> 0 | N24: =IF(Dagen>A24,W24-V24,"") -> 4 | U24: =IF(A24="",0,WEEKDAY(A24,3)) -> 2 | V24: =IF(U24>4,V23,V23+$B$4*8) -> 104 | W24: =VALUE(E24)*24+VALUE(M24)*24+W23 -> 108
A25: =A24+1 -> 44610 | B25: 0.29166667 | C25: 0.52083333 | D25: =IF(C25="","",0.5/24) -> 0.020833333 | E25: =IF(C25="",0,C25-B25-D25) -> 0.20833333 | F25: =IF(E25="","",VALUE(E25)*24) -> 5 | M25: =IF(OR(G25="Semester",G25="Sjuk",G25="Vård av barn"),8/24*$B$4,IF(L25="+",K25-J25,IF(L25="-",(K25-J25)*-1,0))) -> 0 | N25: =IF(Dagen>A25,W25-V25,"") -> 1 | U25: =IF(A25="",0,WEEKDAY(A25,3)) -> 3 | V25: =IF(U25>4,V24,V24+$B$4*8) -> 112 | W25: =VALUE(E25)*24+VALUE(M25)*24+W24 -> 113
A26: =A25+1 -> 44611 | D26: =IF(C26="","",0.5/24) | E26: =IF(C26="",0,C26-B26-D26) -> 0 | F26: =IF(E26="","",VALUE(E26)*24) -> 0 | G26: SEMESTER | M26: =IF(OR(G26="Semester",G26="Sjuk",G26="Vård av barn"),8/24*$B$4,IF(L26="+",K26-J26,IF(L26="-",(K26-J26)*-1,0))) -> 0.33333333 | N26: =IF(Dagen>A26,W26-V26,"") -> 1 | U26: =IF(A26="",0,WEEKDAY(A26,3)) -> 4 | V26: =IF(U26>4,V25,V25+$B$4*8) -> 120 | W26: =VALUE(E26)*24+VALUE(M26)*24+W25 -> 121
A27: =A26+1 -> 44612 | D27: =IF(C27="","",0.5/24) | E27: =IF(C27="",0,C27-B27-D27) -> 0 | F27: =IF(E27="","",VALUE(E27)*24) -> 0 | M27: =IF(OR(G27="Semester",G27="Sjuk",G27="Vård av barn"),8/24*$B$4,IF(L27="+",K27-J27,IF(L27="-",(K27-J27)*-1,0))) -> 0 | N27: =IF(Dagen>A27,W27-V27,"") -> 1 | U27: =IF(A27="",0,WEEKDAY(A27,3)) -> 5 | V27: =IF(U27>4,V26,V26+$B$4*8) -> 120 | W27: =VALUE(E27)*24+VALUE(M27)*24+W26 -> 121
A28: =A27+1 -> 44613 | D28: =IF(C28="","",0.5/24) | E28: =IF(C28="",0,C28-B28-D28) -> 0 | F28: =IF(E28="","",VALUE(E28)*24) -> 0 | M28: =IF(OR(G28="Semester",G28="Sjuk",G28="Vård av barn"),8/24*$B$4,IF(L28="+",K28-J28,IF(L28="-",(K28-J28)*-1,0))) -> 0 | N28: =IF(Dagen>A28,W28-V28,"") -> 1 | U28: =IF(A28="",0,WEEKDAY(A28,3)) -> 6 | V28: =IF(U28>4,V27,V27+$B$4*8) -> 120 | W28: =VALUE(E28)*24+VALUE(M28)*24+W27 -> 121
A29: =A28+1 -> 44614 | B29: 0.29166667 | C29: 0.66666667 | D29: =IF(C29="","",0.5/24) -> 0.020833333 | E29: =IF(C29="",0,C29-B29-D29) -> 0.35416667 | F29: =IF(E29="","",VALUE(E29)*24) -> 8.5 | M29: =IF(OR(G29="Semester",G29="Sjuk",G29="Vård av barn"),8/24*$B$4,IF(L29="+",K29-J29,IF(L29="-",(K29-J29)*-1,0))) -> 0 | N29: =IF(Dagen>A29,W29-V29,"") -> 1.5 | U29: =IF(A29="",0,WEEKDAY(A29,3)) -> 0 | V29: =IF(U29>4,V28,V28+$B$4*8) -> 128 | W29: =VALUE(E29)*24+VALUE(M29)*24+W28 -> 129.5
A30: =A29+1 -> 44615 | B30: 0.29166667 | C30: 0.66666667 | D30: =IF(C30="","",0.5/24) -> 0.020833333 | E30: =IF(C30="",0,C30-B30-D30) -> 0.35416667 | F30: =IF(E30="","",VALUE(E30)*24) -> 8.5 | M30: =IF(OR(G30="Semester",G30="Sjuk",G30="Vård av barn"),8/24*$B$4,IF(L30="+",K30-J30,IF(L30="-",(K30-J30)*-1,0))) -> 0 | N30: =IF(Dagen>A30,W30-V30,"") -> 2 | U30: =IF(A30="",0,WEEKDAY(A30,3)) -> 1 | V30: =IF(U30>4,V29,V29+$B$4*8) -> 136 | W30: =VALUE(E30)*24+VALUE(M30)*24+W29 -> 138
A31: =A30+1 -> 44616 | B31: 0.29166667 | C31: 0.72916667 | D31: =IF(C31="","",0.5/24) -> 0.020833333 | E31: =IF(C31="",0,C31-B31-D31) -> 0.41666667 | F31: =IF(E31="","",VALUE(E31)*24) -> 10 | M31: =IF(OR(G31="Semester",G31="Sjuk",G31="Vård av barn"),8/24*$B$4,IF(L31="+",K31-J31,IF(L31="-",(K31-J31)*-1,0))) -> 0 | N31: =IF(Dagen>A31,W31-V31,"") -> 4 | U31: =IF(A31="",0,WEEKDAY(A31,3)) -> 2 | V31: =IF(U31>4,V30,V30+$B$4*8) -> 144 | W31: =VALUE(E31)*24+VALUE(M31)*24+W30 -> 148
A32: =A31+1 -> 44617 | B32: 0.29166667 | C32: 0.64583333 | D32: =IF(C32="","",0.5/24) -> 0.020833333 | E32: =IF(C32="",0,C32-B32-D32) -> 0.33333333 | F32: =IF(E32="","",VALUE(E32)*24) -> 8 | M32: =IF(OR(G32="Semester",G32="Sjuk",G32="Vård av barn"),8/24*$B$4,IF(L32="+",K32-J32,IF(L32="-",(K32-J32)*-1,0))) -> 0 | N32: =IF(Dagen>A32,W32-V32,"") -> 4 | U32: =IF(A32="",0,WEEKDAY(A32,3)) -> 3 | V32: =IF(U32>4,V31,V31+$B$4*8) -> 152 | W32: =VALUE(E32)*24+VALUE(M32)*24+W31 -> 156
A33: =A32+1 -> 44618 | B33: 0.29166667 | C33: 0.70833333 | D33: =IF(C33="","",0.5/24) -> 0.020833333 | E33: =IF(C33="",0,C33-B33-D33) -> 0.39583333 | F33: =IF(E33="","",VALUE(E33)*24) -> 9.5 | M33: =IF(OR(G33="Semester",G33="Sjuk",G33="Vård av barn"),8/24*$B$4,IF(L33="+",K33-J33,IF(L33="-",(K33-J33)*-1,0))) -> 0 | N33: =IF(Dagen>A33,W33-V33,"") -> 5.5 | U33: =IF(A33="",0,WEEKDAY(A33,3)) -> 4 | V33: =IF(U33>4,V32,V32+$B$4*8) -> 160 | W33: =VALUE(E33)*24+VALUE(M33)*24+W32 -> 165.5
A34: =A33+1 -> 44619 | D34: =IF(C34="","",0.5/24) | E34: =IF(C34="",0,C34-B34-D34) -> 0 | F34: =IF(E34="","",VALUE(E34)*24) -> 0 | M34: =IF(OR(G34="Semester",G34="Sjuk",G34="Vård av barn"),8/24*$B$4,IF(L34="+",K34-J34,IF(L34="-",(K34-J34)*-1,0))) -> 0 | N34: =IF(Dagen>A34,W34-V34,"") -> 5.5 | U34: =IF(A34="",0,WEEKDAY(A34,3)) -> 5 | V34: =IF(U34>4,V33,V33+$B$4*8) -> 160 | W34: =VALUE(E34)*24+VALUE(M34)*24+W33 -> 165.5
P38: =SUM(P7:P37) -> 0 | Q38: =SUM(Q7:Q37) -> 0 | R38: =SUM(R7:R37) -> 0 | S38: =SUM(S7:S37) -> 0 | T38: =SUM(T7:T37) -> 0
A40: =Blankettinfo -> Version 4.6 © LiU 2025-12-03

Sheet mars
A1: Namn | B1: =Namn -> Håkan Stensby | E1: Närvaro | F1: =SUM(F7:F37) -> 143.5 | H1: Referenstid | I1: =VLOOKUP(B3,översikt!A61:C72,3,FALSE)*B4 -> 176
A2: Pnr | B2: =Pnr -> 19770217-6418 | E2: Avvikelse | F2: =VALUE(SUM(M7:M37)*24) -> 0 | H2: Månadens saldo | I2: =IF(F3=0,0,F3-I1) -> -32.5
A3: Månad | B3: =översikt!A63 -> 44620 | E3: Totalt | F3: =F1+F2 -> 143.5 | H3: Ing flex | I3: =februari!I4 -> 13.5
A4: Tj-grad | B4: =Tjgrad -> 1 | E4: Ev korrigering | H4: Utg flex | I4: =IF(N7="", "-", OFFSET(N6, COUNT(N:N), 0, 1, 1) + I3) -> 19.5 | P4: För registrering av tid enligt egna uppdelningar.
B5: Närvarotid | J5: Avvikelser från dagregistreringen | N5: Saldo | P5: (Påverkar inte flextidsredovisningen.) | U5: Dag | V5: Norm | W5: Arb tim ack
A6: Dag | B6: Börjar | C6: Slutar | D6: Lunch | E6: Tim : min | F6: Tim dec | G6: Kommentar | J6: Fr.o.m. kl | K6: T.o.m. kl | L6: + / - | M6: Avvik tim | N6: hittills | O6: Noteringar
A7: =B3 -> 44620 | D7: =IF(C7="","",0.5/24) | E7: =IF(C7="",0,C7-B7-D7) -> 0 | F7: =IF(E7="","",VALUE(E7)*24) -> 0 | M7: =IF(OR(G7="Semester",G7="Sjuk",G7="Vård av barn"),8/24*$B$4,IF(L7="+",K7-J7,IF(L7="-",(K7-J7)*-1,0))) -> 0 | N7: =IF(Dagen>A7,W7-V7,"") -> 0 | U7: =IF(A7="",0,WEEKDAY(A7,3)) -> 6 | V7: =IF(U7>4,V6,V6+$B$4*8) -> 0 | W7: =VALUE(E7)*24+VALUE(M7)*24+W6 -> 0
A8: =A7+1 -> 44621 | B8: 0.29166667 | C8: 0.64583333 | D8: =IF(C8="","",0.5/24) -> 0.020833333 | E8: =IF(C8="",0,C8-B8-D8) -> 0.33333333 | F8: =IF(E8="","",VALUE(E8)*24) -> 8 | M8: =IF(OR(G8="Semester",G8="Sjuk",G8="Vård av barn"),8/24*$B$4,IF(L8="+",K8-J8,IF(L8="-",(K8-J8)*-1,0))) -> 0 | N8: =IF(Dagen>A8,W8-V8,"") -> 0 | U8: =IF(A8="",0,WEEKDAY(A8,3)) -> 0 | V8: =IF(U8>4,V7,V7+$B$4*8) -> 8 | W8: =VALUE(E8)*24+VALUE(M8)*24+W7 -> 8
A9: =A8+1 -> 44622 | B9: 0.29166667 | C9: 0.64583333 | D9: =IF(C9="","",0.5/24) -> 0.020833333 | E9: =IF(C9="",0,C9-B9-D9) -> 0.33333333 | F9: =IF(E9="","",VALUE(E9)*24) -> 8 | M9: =IF(OR(G9="Semester",G9="Sjuk",G9="Vård av barn"),8/24*$B$4,IF(L9="+",K9-J9,IF(L9="-",(K9-J9)*-1,0))) -> 0 | N9: =IF(Dagen>A9,W9-V9,"") -> 0 | U9: =IF(A9="",0,WEEKDAY(A9,3)) -> 1 | V9: =IF(U9>4,V8,V8+$B$4*8) -> 16 | W9: =VALUE(E9)*24+VALUE(M9)*24+W8 -> 16
A10: =A9+1 -> 44623 | B10: 0.29166667 | C10: 0.64583333 | D10: =IF(C10="","",0.5/24) -> 0.020833333 | E10: =IF(C10="",0,C10-B10-D10) -> 0.33333333 | F10: =IF(E10="","",VALUE(E10)*24) -> 8 | M10: =IF(OR(G10="Semester",G10="Sjuk",G10="Vård av barn"),8/24*$B$4,IF(L10="+",K10-J10,IF(L10="-",(K10-J10)*-1,0))) -> 0 | N10: =IF(Dagen>A10,W10-V10,"") -> 0 | U10: =IF(A10="",0,WEEKDAY(A10,3)) -> 2 | V10: =IF(U10>4,V9,V9+$B$4*8) -> 24 | W10: =VALUE(E10)*24+VALUE(M10)*24+W9 -> 24
A11: =A10+1 -> 44624 | B11: 0.29166667 | C11: 0.66666667 | D11: =IF(C11="","",0.5/24) -> 0.020833333 | E11: =IF(C11="",0,C11-B11-D11) -> 0.35416667 | F11: =IF(E11="","",VALUE(E11)*24) -> 8.5 | M11: =IF(OR(G11="Semester",G11="Sjuk",G11="Vård av barn"),8/24*$B$4,IF(L11="+",K11-J11,IF(L11="-",(K11-J11)*-1,0))) -> 0 | N11: =IF(Dagen>A11,W11-V11,"") -> 0.5 | U11: =IF(A11="",0,WEEKDAY(A11,3)) -> 3 | V11: =IF(U11>4,V10,V10+$B$4*8) -> 32 | W11: =VALUE(E11)*24+VALUE(M11)*24+W10 -> 32.5
A12: =A11+1 -> 44625 | B12: 0.29166667 | C12: 0.66666667 | D12: =IF(C12="","",0.5/24) -> 0.020833333 | E12: =IF(C12="",0,C12-B12-D12) -> 0.35416667 | F12: =IF(E12="","",VALUE(E12)*24) -> 8.5 | M12: =IF(OR(G12="Semester",G12="Sjuk",G12="Vård av barn"),8/24*$B$4,IF(L12="+",K12-J12,IF(L12="-",(K12-J12)*-1,0))) -> 0 | N12: =IF(Dagen>A12,W12-V12,"") -> 1 | U12: =IF(A12="",0,WEEKDAY(A12,3)) -> 4 | V12: =IF(U12>4,V11,V11+$B$4*8) -> 40 | W12: =VALUE(E12)*24+VALUE(M12)*24+W11 -> 41
A13: =A12+1 -> 44626 | D13: =IF(C13="","",0.5/24) | E13: =IF(C13="",0,C13-B13-D13) -> 0 | F13: =IF(E13="","",VALUE(E13)*24) -> 0 | M13: =IF(OR(G13="Semester",G13="Sjuk",G13="Vård av barn"),8/24*$B$4,IF(L13="+",K13-J13,IF(L13="-",(K13-J13)*-1,0))) -> 0 | N13: =IF(Dagen>A13,W13-V13,"") -> 1 | U13: =IF(A13="",0,WEEKDAY(A13,3)) -> 5 | V13: =IF(U13>4,V12,V12+$B$4*8) -> 40 | W13: =VALUE(E13)*24+VALUE(M13)*24+W12 -> 41
A14: =A13+1 -> 44627 | D14: =IF(C14="","",0.5/24) | E14: =IF(C14="",0,C14-B14-D14) -> 0 | F14: =IF(E14="","",VALUE(E14)*24) -> 0 | M14: =IF(OR(G14="Semester",G14="Sjuk",G14="Vård av barn"),8/24*$B$4,IF(L14="+",K14-J14,IF(L14="-",(K14-J14)*-1,0))) -> 0 | N14: =IF(Dagen>A14,W14-V14,"") -> 1 | U14: =IF(A14="",0,WEEKDAY(A14,3)) -> 6 | V14: =IF(U14>4,V13,V13+$B$4*8) -> 40 | W14: =VALUE(E14)*24+VALUE(M14)*24+W13 -> 41
A15: =A14+1 -> 44628 | B15: 0.29166667 | C15: 0.64583333 | D15: =IF(C15="","",0.5/24) -> 0.020833333 | E15: =IF(C15="",0,C15-B15-D15) -> 0.33333333 | F15: =IF(E15="","",VALUE(E15)*24) -> 8 | M15: =IF(OR(G15="Semester",G15="Sjuk",G15="Vård av barn"),8/24*$B$4,IF(L15="+",K15-J15,IF(L15="-",(K15-J15)*-1,0))) -> 0 | N15: =IF(Dagen>A15,W15-V15,"") -> 1 | U15: =IF(A15="",0,WEEKDAY(A15,3)) -> 0 | V15: =IF(U15>4,V14,V14+$B$4*8) -> 48 | W15: =VALUE(E15)*24+VALUE(M15)*24+W14 -> 49
A16: =A15+1 -> 44629 | B16: 0.29166667 | C16: 0.64583333 | D16: =IF(C16="","",0.5/24) -> 0.020833333 | E16: =IF(C16="",0,C16-B16-D16) -> 0.33333333 | F16: =IF(E16="","",VALUE(E16)*24) -> 8 | M16: =IF(OR(G16="Semester",G16="Sjuk",G16="Vård av barn"),8/24*$B$4,IF(L16="+",K16-J16,IF(L16="-",(K16-J16)*-1,0))) -> 0 | N16: =IF(Dagen>A16,W16-V16,"") -> 1 | U16: =IF(A16="",0,WEEKDAY(A16,3)) -> 1 | V16: =IF(U16>4,V15,V15+$B$4*8) -> 56 | W16: =VALUE(E16)*24+VALUE(M16)*24+W15 -> 57
A17: =A16+1 -> 44630 | B17: 0.29166667 | C17: 0.66666667 | D17: =IF(C17="","",0.5/24) -> 0.020833333 | E17: =IF(C17="",0,C17-B17-D17) -> 0.35416667 | F17: =IF(E17="","",VALUE(E17)*24) -> 8.5 | M17: =IF(OR(G17="Semester",G17="Sjuk",G17="Vård av barn"),8/24*$B$4,IF(L17="+",K17-J17,IF(L17="-",(K17-J17)*-1,0))) -> 0 | N17: =IF(Dagen>A17,W17-V17,"") -> 1.5 | U17: =IF(A17="",0,WEEKDAY(A17,3)) -> 2 | V17: =IF(U17>4,V16,V16+$B$4*8) -> 64 | W17: =VALUE(E17)*24+VALUE(M17)*24+W16 -> 65.5
A18: =A17+1 -> 44631 | B18: 0.29166667 | C18: 0.66666667 | D18: =IF(C18="","",0.5/24) -> 0.020833333 | E18: =IF(C18="",0,C18-B18-D18) -> 0.35416667 | F18: =IF(E18="","",VALUE(E18)*24) -> 8.5 | M18: =IF(OR(G18="Semester",G18="Sjuk",G18="Vård av barn"),8/24*$B$4,IF(L18="+",K18-J18,IF(L18="-",(K18-J18)*-1,0))) -> 0 | N18: =IF(Dagen>A18,W18-V18,"") -> 2 | U18: =IF(A18="",0,WEEKDAY(A18,3)) -> 3 | V18: =IF(U18>4,V17,V17+$B$4*8) -> 72 | W18: =VALUE(E18)*24+VALUE(M18)*24+W17 -> 74
A19: =A18+1 -> 44632 | B19: 0.29166667 | C19: 0.64583333 | D19: =IF(C19="","",0.5/24) -> 0.020833333 | E19: =IF(C19="",0,C19-B19-D19) -> 0.33333333 | F19: =IF(E19="","",VALUE(E19)*24) -> 8 | M19: =IF(OR(G19="Semester",G19="Sjuk",G19="Vård av barn"),8/24*$B$4,IF(L19="+",K19-J19,IF(L19="-",(K19-J19)*-1,0))) -> 0 | N19: =IF(Dagen>A19,W19-V19,"") -> 2 | U19: =IF(A19="",0,WEEKDAY(A19,3)) -> 4 | V19: =IF(U19>4,V18,V18+$B$4*8) -> 80 | W19: =VALUE(E19)*24+VALUE(M19)*24+W18 -> 82
A20: =A19+1 -> 44633 | D20: =IF(C20="","",0.5/24) | E20: =IF(C20="",0,C20-B20-D20) -> 0 | F20: =IF(E20="","",VALUE(E20)*24) -> 0 | M20: =IF(OR(G20="Semester",G20="Sjuk",G20="Vård av barn"),8/24*$B$4,IF(L20="+",K20-J20,IF(L20="-",(K20-J20)*-1,0))) -> 0 | N20: =IF(Dagen>A20,W20-V20,"") -> 2 | U20: =IF(A20="",0,WEEKDAY(A20,3)) -> 5 | V20: =IF(U20>4,V19,V19+$B$4*8) -> 80 | W20: =VALUE(E20)*24+VALUE(M20)*24+W19 -> 82
A21: =A20+1 -> 44634 | D21: =IF(C21="","",0.5/24) | E21: =IF(C21="",0,C21-B21-D21) -> 0 | F21: =IF(E21="","",VALUE(E21)*24) -> 0 | M21: =IF(OR(G21="Semester",G21="Sjuk",G21="Vård av barn"),8/24*$B$4,IF(L21="+",K21-J21,IF(L21="-",(K21-J21)*-1,0))) -> 0 | N21: =IF(Dagen>A21,W21-V21,"") -> 2 | U21: =IF(A21="",0,WEEKDAY(A21,3)) -> 6 | V21: =IF(U21>4,V20,V20+$B$4*8) -> 80 | W21: =VALUE(E21)*24+VALUE(M21)*24+W20 -> 82
A22: =A21+1 -> 44635 | B22: 0.29166667 | C22: 0.64583333 | D22: =IF(C22="","",0.5/24) -> 0.020833333 | E22: =IF(C22="",0,C22-B22-D22) -> 0.33333333 | F22: =IF(E22="","",VALUE(E22)*24) -> 8 | M22: =IF(OR(G22="Semester",G22="Sjuk",G22="Vård av barn"),8/24*$B$4,IF(L22="+",K22-J22,IF(L22="-",(K22-J22)*-1,0))) -> 0 | N22: =IF(Dagen>A22,W22-V22,"") -> 2 | U22: =IF(A22="",0,WEEKDAY(A22,3)) -> 0 | V22: =IF(U22>4,V21,V21+$B$4*8) -> 88 | W22: =VALUE(E22)*24+VALUE(M22)*24+W21 -> 90
A23: =A22+1 -> 44636 | B23: 0.29166667 | C23: 0.66666667 | D23: =IF(C23="","",0.5/24) -> 0.020833333 | E23: =IF(C23="",0,C23-B23-D23) -> 0.35416667 | F23: =IF(E23="","",VALUE(E23)*24) -> 8.5 | M23: =IF(OR(G23="Semester",G23="Sjuk",G23="Vård av barn"),8/24*$B$4,IF(L23="+",K23-J23,IF(L23="-",(K23-J23)*-1,0))) -> 0 | N23: =IF(Dagen>A23,W23-V23,"") -> 2.5 | U23: =IF(A23="",0,WEEKDAY(A23,3)) -> 1 | V23: =IF(U23>4,V22,V22+$B$4*8) -> 96 | W23: =VALUE(E23)*24+VALUE(M23)*24+W22 -> 98.5
A24: =A23+1 -> 44637 | B24: 0.29166667 | C24: 0.70833333 | D24: =IF(C24="","",0.5/24) -> 0.020833333 | E24: =IF(C24="",0,C24-B24-D24) -> 0.39583333 | F24: =IF(E24="","",VALUE(E24)*24) -> 9.5 | M24: =IF(OR(G24="Semester",G24="Sjuk",G24="Vård av barn"),8/24*$B$4,IF(L24="+",K24-J24,IF(L24="-",(K24-J24)*-1,0))) -> 0 | N24: =IF(Dagen>A24,W24-V24,"") -> 4 | U24: =IF(A24="",0,WEEKDAY(A24,3)) -> 2 | V24: =IF(U24>4,V23,V23+$B$4*8) -> 104 | W24: =VALUE(E24)*24+VALUE(M24)*24+W23 -> 108
A25: =A24+1 -> 44638 | B25: 0.29166667 | C25: 0.66666667 | D25: =IF(C25="","",0.5/24) -> 0.020833333 | E25: =IF(C25="",0,C25-B25-D25) -> 0.35416667 | F25: =IF(E25="","",VALUE(E25)*24) -> 8.5 | M25: =IF(OR(G25="Semester",G25="Sjuk",G25="Vård av barn"),8/24*$B$4,IF(L25="+",K25-J25,IF(L25="-",(K25-J25)*-1,0))) -> 0 | N25: =IF(Dagen>A25,W25-V25,"") -> 4.5 | U25: =IF(A25="",0,WEEKDAY(A25,3)) -> 3 | V25: =IF(U25>4,V24,V24+$B$4*8) -> 112 | W25: =VALUE(E25)*24+VALUE(M25)*24+W24 -> 116.5
A26: =A25+1 -> 44639 | B26: 0.29166667 | C26: 0.70833333 | D26: =IF(C26="","",0.5/24) -> 0.020833333 | E26: =IF(C26="",0,C26-B26-D26) -> 0.39583333 | F26: =IF(E26="","",VALUE(E26)*24) -> 9.5 | M26: =IF(OR(G26="Semester",G26="Sjuk",G26="Vård av barn"),8/24*$B$4,IF(L26="+",K26-J26,IF(L26="-",(K26-J26)*-1,0))) -> 0 | N26: =IF(Dagen>A26,W26-V26,"") -> 6 | U26: =IF(A26="",0,WEEKDAY(A26,3)) -> 4 | V26: =IF(U26>4,V25,V25+$B$4*8) -> 120 | W26: =VALUE(E26)*24+VALUE(M26)*24+W25 -> 126
A27: =A26+1 -> 44640 | B27: 0.29166667 | D27: =IF(C27="","",0.5/24) | E27: =IF(C27="",0,C27-B27-D27) -> 0 | F27: =IF(E27="","",VALUE(E27)*24) -> 0 | M27: =IF(OR(G27="Semester",G27="Sjuk",G27="Vård av barn"),8/24*$B$4,IF(L27="+",K27-J27,IF(L27="-",(K27-J27)*-1,0))) -> 0 | N27: =IF(Dagen>A27,W27-V27,"") -> 6 | U27: =IF(A27="",0,WEEKDAY(A27,3)) -> 5 | V27: =IF(U27>4,V26,V26+$B$4*8) -> 120 | W27: =VALUE(E27)*24+VALUE(M27)*24+W26 -> 126
A28: =A27+1 -> 44641 | D28: =IF(C28="","",0.5/24) | E28: =IF(C28="",0,C28-B28-D28) -> 0 | F28: =IF(E28="","",VALUE(E28)*24) -> 0 | M28: =IF(OR(G28="Semester",G28="Sjuk",G28="Vård av barn"),8/24*$B$4,IF(L28="+",K28-J28,IF(L28="-",(K28-J28)*-1,0))) -> 0 | N28: =IF(Dagen>A28,W28-V28,"") -> 6 | U28: =IF(A28="",0,WEEKDAY(A28,3)) -> 6 | V28: =IF(U28>4,V27,V27+$B$4*8) -> 120 | W28: =VALUE(E28)*24+VALUE(M28)*24+W27 -> 126
A29: =A28+1 -> 44642 | B29: 0.29166667 | C29: 0.64583333 | D29: =IF(C29="","",0.5/24) -> 0.020833333 | E29: =IF(C29="",0,C29-B29-D29) -> 0.33333333 | F29: =IF(E29="","",VALUE(E29)*24) -> 8 | M29: =IF(OR(G29="Semester",G29="Sjuk",G29="Vård av barn"),8/24*$B$4,IF(L29="+",K29-J29,IF(L29="-",(K29-J29)*-1,0))) -> 0 | N29: =IF(Dagen>A29,W29-V29,"") -> 6 | U29: =IF(A29="",0,WEEKDAY(A29,3)) -> 0 | V29: =IF(U29>4,V28,V28+$B$4*8) -> 128 | W29: =VALUE(E29)*24+VALUE(M29)*24+W28 -> 134
A30: =A29+1 -> 44643 | B30: 0.29166667 | C30: 0.70833333 | D30: =IF(C30="","",0.5/24) -> 0.020833333 | E30: =IF(C30="",0,C30-B30-D30) -> 0.39583333 | F30: =IF(E30="","",VALUE(E30)*24) -> 9.5 | M30: =IF(OR(G30="Semester",G30="Sjuk",G30="Vård av barn"),8/24*$B$4,IF(L30="+",K30-J30,IF(L30="-",(K30-J30)*-1,0))) -> 0 | N30: =IF(Dagen>A30,W30-V30,"") | U30: =IF(A30="",0,WEEKDAY(A30,3)) -> 1 | V30: =IF(U30>4,V29,V29+$B$4*8) -> 136 | W30: =VALUE(E30)*24+VALUE(M30)*24+W29 -> 143.5
A31: =A30+1 -> 44644 | B31: 0.29166667 | D31: =IF(C31="","",0.5/24) | E31: =IF(C31="",0,C31-B31-D31) -> 0 | F31: =IF(E31="","",VALUE(E31)*24) -> 0 | M31: =IF(OR(G31="Semester",G31="Sjuk",G31="Vård av barn"),8/24*$B$4,IF(L31="+",K31-J31,IF(L31="-",(K31-J31)*-1,0))) -> 0 | N31: =IF(Dagen>A31,W31-V31,"") | U31: =IF(A31="",0,WEEKDAY(A31,3)) -> 2 | V31: =IF(U31>4,V30,V30+$B$4*8) -> 144 | W31: =VALUE(E31)*24+VALUE(M31)*24+W30 -> 143.5
A32: =A31+1 -> 44645 | B32: 0.29166667 | D32: =IF(C32="","",0.5/24) | E32: =IF(C32="",0,C32-B32-D32) -> 0 | F32: =IF(E32="","",VALUE(E32)*24) -> 0 | M32: =IF(OR(G32="Semester",G32="Sjuk",G32="Vård av barn"),8/24*$B$4,IF(L32="+",K32-J32,IF(L32="-",(K32-J32)*-1,0))) -> 0 | N32: =IF(Dagen>A32,W32-V32,"") | U32: =IF(A32="",0,WEEKDAY(A32,3)) -> 3 | V32: =IF(U32>4,V31,V31+$B$4*8) -> 152 | W32: =VALUE(E32)*24+VALUE(M32)*24+W31 -> 143.5
A33: =A32+1 -> 44646 | B33: 0.29166667 | D33: =IF(C33="","",0.5/24) | E33: =IF(C33="",0,C33-B33-D33) -> 0 | F33: =IF(E33="","",VALUE(E33)*24) -> 0 | M33: =IF(OR(G33="Semester",G33="Sjuk",G33="Vård av barn"),8/24*$B$4,IF(L33="+",K33-J33,IF(L33="-",(K33-J33)*-1,0))) -> 0 | N33: =IF(Dagen>A33,W33-V33,"") | U33: =IF(A33="",0,WEEKDAY(A33,3)) -> 4 | V33: =IF(U33>4,V32,V32+$B$4*8) -> 160 | W33: =VALUE(E33)*24+VALUE(M33)*24+W32 -> 143.5
A34: =A33+1 -> 44647 | D34: =IF(C34="","",0.5/24) | E34: =IF(C34="",0,C34-B34-D34) -> 0 | F34: =IF(E34="","",VALUE(E34)*24) -> 0 | M34: =IF(OR(G34="Semester",G34="Sjuk",G34="Vård av barn"),8/24*$B$4,IF(L34="+",K34-J34,IF(L34="-",(K34-J34)*-1,0))) -> 0 | N34: =IF(Dagen>A34,W34-V34,"") | U34: =IF(A34="",0,WEEKDAY(A34,3)) -> 5 | V34: =IF(U34>4,V33,V33+$B$4*8) -> 160 | W34: =VALUE(E34)*24+VALUE(M34)*24+W33 -> 143.5
A35: =A34+1 -> 44648 | D35: =IF(C35="","",0.5/24) | E35: =IF(C35="",0,C35-B35-D35) -> 0 | F35: =IF(E35="","",VALUE(E35)*24) -> 0 | M35: =IF(OR(G35="Semester",G35="Sjuk",G35="Vård av barn"),8/24*$B$4,IF(L35="+",K35-J35,IF(L35="-",(K35-J35)*-1,0))) -> 0 | N35: =IF(Dagen>A35,W35-V35,"") | U35: =IF(A35="",0,WEEKDAY(A35,3)) -> 6 | V35: =IF(U35>4,V34,V34+$B$4*8) -> 160 | W35: =VALUE(E35)*24+VALUE(M35)*24+W34 -> 143.5
A36: =A35+1 -> 44649 | D36: =IF(C36="","",0.5/24) | E36: =IF(C36="",0,C36-B36-D36) -> 0 | F36: =IF(E36="","",VALUE(E36)*24) -> 0 | M36: =IF(OR(G36="Semester",G36="Sjuk",G36="Vård av barn"),8/24*$B$4,IF(L36="+",K36-J36,IF(L36="-",(K36-J36)*-1,0))) -> 0 | N36: =IF(Dagen>A36,W36-V36,"") | U36: =IF(A36="",0,WEEKDAY(A36,3)) -> 0 | V36: =IF(U36>4,V35,V35+$B$4*8) -> 168 | W36: =VALUE(E36)*24+VALUE(M36)*24+W35 -> 143.5
A37: =A36+1 -> 44650 | D37: =IF(C37="","",0.5/24) | E37: =IF(C37="",0,C37-B37-D37) -> 0 | F37: =IF(E37="","",VALUE(E37)*24) -> 0 | M37: =IF(OR(G37="Semester",G37="Sjuk",G37="Vård av barn"),8/24*$B$4,IF(L37="+",K37-J37,IF(L37="-",(K37-J37)*-1,0))) -> 0 | N37: =IF(Dagen>A37,W37-V37,"") | U37: =IF(A37="",0,WEEKDAY(A37,3)) -> 1 | V37: =IF(U37>4,V36,V36+$B$4*8) -> 176 | W37: =VALUE(E37)*24+VALUE(M37)*24+W36 -> 143.5
P38: =SUM(P7:P37) -> 0 | Q38: =SUM(Q7:Q37) -> 0 | R38: =SUM(R7:R37) -> 0 | S38: =SUM(S7:S37) -> 0 | T38: =SUM(T7:T37) -> 0
A40: =Blankettinfo -> Version 4.6 © LiU 2025-12-03

Sheet april
A1: Namn | B1: =Namn -> Håkan Stensby | E1: Närvaro | F1: =SUM(F7:F37) -> 0 | H1: Referenstid | I1: =VLOOKUP(B3,översikt!A61:C72,3,FALSE)*B4 -> 160
A2: Pnr | B2: =Pnr -> 19770217-6418 | E2: Avvikelse | F2: =VALUE(SUM(M7:M37)*24) -> 0 | H2: Månadens saldo | I2: =IF(F3=0,0,F3-I1) -> 0
A3: Månad | B3: =översikt!A64 -> 44651 | E3: Totalt | F3: =F1+F2 -> 0 | H3: Ing flex | I3: =mars!I4 -> 19.5
A4: Tj-grad | B4: =Tjgrad -> 1 | E4: Ev korrigering | H4: Utg flex | I4: =IF(N7="", "-", OFFSET(N6, COUNT(N:N), 0, 1, 1) + I3) -> - | P4: För registrering av tid enligt egna uppdelningar.
B5: Närvarotid | J5: Avvikelser från dagregistreringen | N5: Saldo | P5: (Påverkar inte flextidsredovisningen.) | U5: Dag | V5: Norm | W5: Arb tim ack
A6: Dag | B6: Börjar | C6: Slutar | D6: Lunch | E6: Tim : min | F6: Tim dec | G6: Kommentar | J6: Fr.o.m. kl | K6: T.o.m. kl | L6: + / - | M6: Avvik tim | N6: hittills | O6: Noteringar
A7: =B3 -> 44651 | D7: =IF(C7="","",0.5/24) | E7: =IF(C7="",0,C7-B7-D7) -> 0 | F7: =IF(E7="","",VALUE(E7)*24) -> 0 | M7: =IF(OR(G7="Semester",G7="Sjuk",G7="Vård av barn"),8/24*$B$4,IF(L7="+",K7-J7,IF(L7="-",(K7-J7)*-1,0))) -> 0 | N7: =IF(Dagen>A7,W7-V7,"") | U7: =IF(A7="",0,WEEKDAY(A7,3)) -> 2 | V7: =IF(U7>4,V6,V6+$B$4*8) -> 8 | W7: =VALUE(E7)*24+VALUE(M7)*24+W6 -> 0
A8: =A7+1 -> 44652 | D8: =IF(C8="","",0.5/24) | E8: =IF(C8="",0,C8-B8-D8) -> 0 | F8: =IF(E8="","",VALUE(E8)*24) -> 0 | M8: =IF(OR(G8="Semester",G8="Sjuk",G8="Vård av barn"),8/24*$B$4,IF(L8="+",K8-J8,IF(L8="-",(K8-J8)*-1,0))) -> 0 | N8: =IF(Dagen>A8,W8-V8,"") | U8: =IF(A8="",0,WEEKDAY(A8,3)) -> 3 | V8: =IF(U8>4,V7,V7+$B$4*8) -> 16 | W8: =VALUE(E8)*24+VALUE(M8)*24+W7 -> 0
A9: =A8+1 -> 44653 | D9: =IF(C9="","",0.5/24) | E9: =IF(C9="",0,C9-B9-D9) -> 0 | F9: =IF(E9="","",VALUE(E9)*24) -> 0 | G9: Långfredagen | M9: =IF(OR(G9="Semester",G9="Sjuk",G9="Vård av barn"),8/24*$B$4,IF(L9="+",K9-J9,IF(L9="-",(K9-J9)*-1,0))) -> 0 | N9: =IF(Dagen>A9,W9-V9,"") | U9: 8 | V9: =IF(U9>4,V8,V8+$B$4*8) -> 16 | W9: =VALUE(E9)*24+VALUE(M9)*24+W8 -> 0
A10: =A9+1 -> 44654 | D10: =IF(C10="","",0.5/24) | E10: =IF(C10="",0,C10-B10-D10) -> 0 | F10: =IF(E10="","",VALUE(E10)*24) -> 0 | M10: =IF(OR(G10="Semester",G10="Sjuk",G10="Vård av barn"),8/24*$B$4,IF(L10="+",K10-J10,IF(L10="-",(K10-J10)*-1,0))) -> 0 | N10: =IF(Dagen>A10,W10-V10,"") | U10: =IF(A10="",0,WEEKDAY(A10,3)) -> 5 | V10: =IF(U10>4,V9,V9+$B$4*8) -> 16 | W10: =VALUE(E10)*24+VALUE(M10)*24+W9 -> 0
